Workbook

Sheet Journal
B2: date | C2: Temps | D2: type de travail | E2: description | G2: type de travail | H2: somme
B3: 20.01.2026 | C3: 0.125 | D3: Cours | E3: Introduction au module 5. Prise de notes. | G3: Cours | H3: =SUMIF(Journal[type de travail],types[[#This Row],[type de travail]],Journal[Temps])*24 -> 3 | I3: =types[[#This Row],[somme]]/$H$11 -> 0.023195876 | J3: {=_xlfn._xlws.FILTER(G3:G10,H3:H10>0)} -> Cours | K3: {=_xlfn._xlws.FILTER(H3:H10,H3:H10>0)} -> 3
B4: 20.01.2026 | C4: 0.041666667 | D4: Recherche | E4: Recherche d'idée de projet. | G4: Plannification | H4: =SUMIF(Journal[type de travail],types[[#This Row],[type de travail]],Journal[Temps])*24 -> 3 | I4: =types[[#This Row],[somme]]/$H$11 -> 0.023195876 | J4: Plannification | K4: 3
B5: 27.01.2026 | C5: 0.125 | D5: Documentation | E5: Création du cahier des charge, validation avec responsable du module. Création de la documentation technique. | G5: Recherche | H5: =SUMIF(Journal[type de travail],types[[#This Row],[type de travail]],Journal[Temps])*24 -> 9 | I5: =types[[#This Row],[somme]]/$H$11 -> 0.069587629 | J5: Recherche | K5: 9
B6: 27.01.2026 | C6: 0.041666667 | D6: Recherche | E6: Recherche et configuration de solution GitHub. Clés SSH. | G6: Maquettage | H6: =SUMIF(Journal[type de travail],types[[#This Row],[type de travail]],Journal[Temps])*24 -> 17 | I6: =types[[#This Row],[somme]]/$H$11 -> 0.1314433 | J6: Maquettage | K6: 17
B7: 27.01.2026 | C7: 0.041666667 | D7: Recherche | E7: Recherche d'une application pour faire une maquette | G7: Documentation | H7: =SUMIF(Journal[type de travail],types[[#This Row],[type de travail]],Journal[Temps])*24 -> 37.5 | I7: =types[[#This Row],[somme]]/$H$11 -> 0.28994845 | J7: Documentation | K7: 37.5
B8: 30.01.2026 | C8: 0.125 | D8: Recherche | E8: Recherche d'une application pour faire une maquette + Lecture de la documentation de l'outil Penpot | G8: Programmation | H8: =SUMIF(Journal[type de travail],types[[#This Row],[type de travail]],Journal[Temps])*24 -> 58.5 | I8: =types[[#This Row],[somme]]/$H$11 -> 0.45231959 | J8: Programmation | K8: 58.5
B9: 30.01.2026 | C9: 0.16666667 | D9: Maquettage | E9: Commencement de la maquette de l'application | G9: Tests | H9: =SUMIF(Journal[type de travail],types[[#This Row],[type de travail]],Journal[Temps])*24 -> 1.3333333 | I9: =types[[#This Row],[somme]]/$H$11 -> 0.010309278 | J9: Tests | K9: 1.3333333
B10: 03.02.2026 | C10: 0.083333333 | D10: Documentation | E10: Finalisation de l'introduction du projet. | G10: Présentation | H10: =SUMIF(Journal[type de travail],types[[#This Row],[type de travail]],Journal[Temps])*24 -> 0 | I10: =types[[#This Row],[somme]]/$H$11 -> 0
B11: 03.02.2026 | C11: 0.041666667 | D11: Documentation | E11: Ajout de la licence du projet et ajout de l'interface dans le dépot GitHub | G11: Somme | H11: =SUM(H3:H10) -> 129.33333
B12: 03.02.2026 | C12: 0.041666667 | D12: Plannification | E12: Commencement de la plannification du projet
B13: 03.02.2026 | C13: 0.083333333 | D13: Documentation | E13: Révision de la licence et des citation des ressources GPL3.0-Only parce que l'opensource c'est génial. Ajout du chapitre public cible dans la documentation technique.
B14: 04.02.2026 | C14: 0.083333333 | D14: Documentation | E14: Commencement de la documentation sur l'exigence de l'application.
B15: 04.02.2026 | C15: 0.125 | D15: Documentation | E15: Création de diagrammes (cas utilisation, MCD, classe), mis en pause, analyse pas terminé.
B16: 06.02.2026 | C16: 0.125 | D16: Documentation | E16: Finalisation de la documentation analyse de l'application.
B17: 06.02.2026 | C17: 0.16666667 | D17: Documentation | E17: Commencement du chapitre conception de l'applicaiton. MCD et Diagramme de Classes. Relecture du document.
B18: 08.02.2026 | C18: 0.083333333 | D18: Plannification | E18: Plannification du projet terminé
B19: 09.02.2026 | C19: 0.041666667 | D19: Documentation | E19: Diagramme de classe (interraction avec la BDD)
B20: 10.02.2026 | C20: 0.083333333 | D20: Programmation | E20: Test de programmation SQLite + Classes
B21: 10.02.2026 | C21: 0.083333333 | D21: Maquettage | E21: Commencement du design du menu Journal
B22: 10.02.2026 | C22: 0.125 | D22: Maquettage | E22: Finalisation menu Note
B23: 12.02.2026 | C23: 0.083333333 | D23: Maquettage | E23: Finalisation du menu Journal
... B29: 05.03.2026 | C29: 0.125 | D29: Documentation | E29: Documentation de la maquette
B30: 46087 | C30: 0.16666667 | D30: Programmation | E30: Implémentation des police, couleur, themes et propriété d'affichage. Reflexion sur la possibilité d'avoir un thème sombre ET claire.
B31: 46087 | C31: 0.020833333 | D31: Tests | E31: Test de fonctionnement sur Windows, Linux et MacOS. Fonctionnel.
B32: 46088 | C32: 0.25 | D32: Programmation | E32: Ajout des boutons de navigation entre les pages. Ajout de la page paramète. Implémentation du changement de thème et de la séléction du fichier BDD.db. Ajout d'une démonstration de la page d'accueil avec les notes (moyenne et tendances).
B33: 46091 | C33: 0.020833333 | D33: Documentation | E33: Documentation des différents fichiers (code) du projet.
B34: 46091 | C34: 0.10416667 | D34: Documentation | E34: Documentation des ressources globale et de la page paramètres. Relecture et correction du document.
B35: 46091 | C35: 0.020833333 | D35: Programmation | E35: Modification de l'aboressance du projet
B36: 46091 | C36: 0.14583333 | D36: Programmation | E36: Intégration de la vrai BDD + optimisation des ressources
B37: 46093 | C37: 0.083333333 | D37: Programmation | E37: Ajout de l'animation de l'affichage + ajout de l'éritage des classes (ModelView)
B38: 46095 | C38: 0.1875 | D38: Programmation | E38: Intégration du graphique des répatition des heures dans Accueil. Correction du calcul de la moyenne (ajout en tant que composant réutilisable). Correction de l'affichage des module (selection mode).
B39: 46087 | C39: 0.020833333 | D39: Tests | E39: Test de fonctionnement sur Windows, Linux et MacOS. Fonctionnel.
B40: 46096 | C40: 0.10416667 | D40: Documentation | E40: Ajout du journal actuel dans la BDD
B41: 46096 | C41: 0.10416667 | D41: Programmation | E41: Ajout du chargement des données en service. Optimisation chargement des pages. Ajout du curseur de navigation. Ajout de la somme d'heures dans le graphique.
... B50: 46103 | C50: 0.16666667 | D50: Programmation | E50: Implémentation et séparation des responsabilités dans des classes séparés. WorkFlow en mémoire et Blob pour la souvegarde dans SQLite fonctionnel. (sans test d'injection du blob)
B51: 46103 | C51: 0.20833333 | D51: Programmation | E51: Finalisation du PoC. Très concluant, fonctionnel et fluide. Merge de la branche PDF -> Main. | G51: <-- A jour avec la BDD
B52: 46104 | C52: 0.013888889 | D52: Tests | E52: Test de fonctionnement sur Windows, Linux et MacOS. Fonctionnel. Correction d'un dépendance sur Linux
B53: 46117 | C53: 0.125 | D53: Programmation | E53: Ajout de l'interface pour éditer les modules
B54: 46118 | C54: 0.083333333 | D54: Programmation | E54: Implémentation des intéractions avec la BDD pour la gestion de module

Sheet SommeParJours
A1: date | B1: somme
A2: {=_xlfn.UNIQUE(Journal[date])} -> 20.01.2026 | B2: =SUMIF(Journal[date],SommeParJours!A2,Journal[Temps]) -> 0.16666667
A3: 27.01.2026 | B3: =SUMIF(Journal[date],SommeParJours!A3,Journal[Temps]) -> 0.20833333
A4: 30.01.2026 | B4: =SUMIF(Journal[date],SommeParJours!A4,Journal[Temps]) -> 0.29166667
A5: 03.02.2026 | B5: =SUMIF(Journal[date],SommeParJours!A5,Journal[Temps]) -> 0.25
A6: 04.02.2026 | B6: =SUMIF(Journal[date],SommeParJours!A6,Journal[Temps]) -> 0.20833333
A7: 06.02.2026 | B7: =SUMIF(Journal[date],SommeParJours!A7,Journal[Temps]) -> 0.29166667
A8: 08.02.2026 | B8: =SUMIF(Journal[date],SommeParJours!A8,Journal[Temps]) -> 0.083333333
A9: 09.02.2026 | B9: =SUMIF(Journal[date],SommeParJours!A9,Journal[Temps]) -> 0.041666667
A10: 10.02.2026 | B10: =SUMIF(Journal[date],SommeParJours!A10,Journal[Temps]) -> 0.29166667
A11: 12.02.2026 | B11: =SUMIF(Journal[date],SommeParJours!A11,Journal[Temps]) -> 0.083333333
A12: 13.02.2026 | B12: =SUMIF(Journal[date],SommeParJours!A12,Journal[Temps]) -> 0.0625
A13: 24.02.2026 | B13: =SUMIF(Journal[date],SommeParJours!A13,Journal[Temps]) -> 0.125
A14: 03.03.2026 | B14: =SUMIF(Journal[date],SommeParJours!A14,Journal[Temps]) -> 0.20833333
A15: 05.03.2026 | B15: =SUMIF(Journal[date],SommeParJours!A15,Journal[Temps]) -> 0.1875
A16: 46087 | B16: =SUMIF(Journal[date],SommeParJours!A16,Journal[Temps]) -> 0.20833333
A17: 46088 | B17: =SUMIF(Journal[date],SommeParJours!A17,Journal[Temps]) -> 0.25
A18: 46091 | B18: =SUMIF(Journal[date],SommeParJours!A18,Journal[Temps]) -> 0.29166667
A19: 46093 | B19: =SUMIF(Journal[date],SommeParJours!A19,Journal[Temps]) -> 0.083333333
A20: 46095 | B20: =SUMIF(Journal[date],SommeParJours!A20,Journal[Temps]) -> 0.1875
A21: 46096 | B21: =SUMIF(Journal[date],SommeParJours!A21,Journal[Temps]) -> 0.20833333
A22: 46097 | B22: =SUMIF(Journal[date],SommeParJours!A22,Journal[Temps]) -> 0.14583333
A23: 46098 | B23: =SUMIF(Journal[date],SommeParJours!A23,Journal[Temps]) -> 0.16666667
A24: 46099 | B24: =SUMIF(Journal[date],SommeParJours!A24,Journal[Temps]) -> 0.20833333
A25: 46100 | B25: =SUMIF(Journal[date],SommeParJours!A25,Journal[Temps]) -> 0.33333333
A26: 46102 | B26: =SUMIF(Journal[date],SommeParJours!A26,Journal[Temps]) -> 0.20833333 | C26: =SUMIF(Journal[date],SommeParJours!A26,Journal[Temps]) -> 0.20833333
A27: 46103 | B27: =SUMIF(Journal[date],SommeParJours!A27,Journal[Temps]) -> 0.375 | C27: =SUMIF(Journal[date],SommeParJours!A27,Journal[Temps]) -> 0.375
A28: 46104 | C28: =SUMIF(Journal[date],SommeParJours!A28,Journal[Temps]) -> 0.013888889
A29: 46117 | C29: =SUMIF(Journal[date],SommeParJours!A29,Journal[Temps]) -> 0.125
A30: 46118 | C30: =SUMIF(Journal[date],SommeParJours!A30,Journal[Temps]) -> 0.083333333
C31: =SUMIF(Journal[date],SommeParJours!A31,Journal[Temps]) -> 0
C32: =SUMIF(Journal[date],SommeParJours!A32,Journal[Temps]) -> 0
C33: =SUMIF(Journal[date],SommeParJours!A33,Journal[Temps]) -> 0
C34: =SUMIF(Journal[date],SommeParJours!A34,Journal[Temps]) -> 0
C35: =SUMIF(Journal[date],SommeParJours!A35,Journal[Temps]) -> 0
C36: =SUMIF(Journal[date],SommeParJours!A36,Journal[Temps]) -> 0
C37: =SUMIF(Journal[date],SommeParJours!A37,Journal[Temps]) -> 0
C38: =SUMIF(Journal[date],SommeParJours!A38,Journal[Temps]) -> 0
C39: =SUMIF(Journal[date],SommeParJours!A39,Journal[Temps]) -> 0
B40: =IF(C40>0,C40,"") | C40: =SUMIF(Journal[date],SommeParJours!A40,Journal[Temps]) -> 0
...

Sheet Plannification
B1: Phases | C1: Tâche | D1: 20.01.2026 | E1: 26.01.2026 | F1: 27.01.2026 | G1: 30.01.2026 | H1: 02.02.2026 | I1: 03.02.2026 | J1: 09.02.2026 | K1: 10.03.2026 | L1: Vacances (16-20 fev.) | M1: 23.02.2026 | N1: 24.02.2026 | O1: 02.03.2026 | P1: 03.03.2026 | Q1: 10.03.2026 | R1: 16.03.2026 | S1: 17.03.2026 | T1: 24.03.2026 | U1: 30.03.2026 | V1: 31.03.2026 | W1: Vacances (6-18 avr.) | X1: 20.04.2026 | Y1: 21.04.2026 | Z1: 28.04.2026 | AA1: 04.05.2026 | AB1: 05.05.2026 | AC1: 12.05.2026 | AD1: Absent (18-22 Mai) | AE1: 26.05.2026 | AF1: 01.06.2026 | AG1: 02.06.2026 | AH1: 08.06.2026 | AI1: 09.06.2026 | AJ1: 11.06.2026 | AK1: 17.06.2026
B2: Documentation | C2: Plannification
C4: Création dépot GitHub
C6: Documentation
C8: Journal de travail
C10: Mode d'emplois
C12: Préparation à la présentation
B14: Analyse | C14: Trouver et tester un framework
C16: Trouver une idée de projet
C18: Décrire le projet et valider
C20: Lister les besoins
C22: Lister les choix de départ (technologie)
C24: Choisir une architecture de l'application
B26: Conception | C26: Modélisation BDD
C28: Diagrammes UML
C30: Maquette de l'application (interractif)
C32: Test + correction de la maquette
B34: Implémentation | C34: Codage des classes
C36: Codage de l'interration avec la BDD
C38: Mise en place du MVVM
C40: Implémentation de l'interface
B42: Tests | C42: Test fonctionnement de l'application
C44: Correction du code
B46: Jalons | C46: Présentation
AN47: Planifié
C48: Remise du travail complet | AN48: Dans les temps
AN49: Retard

Sheet PlanificationExemple
B2: Phases | C2: Tâche | D2: Mois | E2: Octobre | F2: Novembre | J2: Décembre | N2: Janvier | R2: Février
D3: S | E3: 4 | F3: 1 | G3: 2 | H3: 3 | I3: 4 | J3: 1 | K3: 2 | L3: 3 | M3: 4 | N3: 1 | O3: 2 | P3: 3 | Q3: 4 | R3: 1 | S3: 2 | U3: 10 semaines à 5 périodes
B4: Étude des besoins | C4: Organigramme | U4: De octobre 2025 à janvier 2026
C6: Service réseau | U6: Remise : 11.02.2026
U7: Présentation : ?
C8: Nombre de nœuds | U8: Remédiation : ?
C10: Sécurité
B12: Conception Logique | C12: Topologie logique
C14: Plan d'adressage IPv4 et IPv6
C16: Planification du projet
B18: Analyse impl. | C18: Plan physique
C20: Liste de matériels
C22: Mise en place de la sécurité
B24: Simulation | C24: Création du réseau sur packet tracer
C26: Test du réseau
C28: Debug du réseau + checklist
B30: Documentation | C30: Journal de travail
C32: Documentation
C34: Préparation a la présentation | V34: Planifiée
V35: Effective
